2025-07-05 23:22:57,202 - __main__ - INFO - ==================================================
2025-07-05 23:22:57,202 - __main__ - INFO - 应用程序启动 - 日志系统初始化完成
2025-07-05 23:22:57,202 - __main__ - INFO - 日志文件路径: D:\pythonProject\generateTestCases\logs\app_20250705_232257.log
2025-07-05 23:22:57,202 - __main__ - INFO - ==================================================
2025-07-05 23:22:57,202 - __main__ - INFO - 启动 frpc: D:\pythonProject\generateTestCases\frpc.exe -c D:\pythonProject\generateTestCases\frpc.toml
2025-07-05 23:22:57,265 - __main__ - INFO - frpc 启动成功
2025-07-05 23:22:57,303 - main - INFO - ==================================================
2025-07-05 23:22:57,303 - main - INFO - 应用程序启动 - 日志系统初始化完成
2025-07-05 23:22:57,303 - main - INFO - 日志文件路径: D:\pythonProject\generateTestCases\logs\app_20250705_232257.log
2025-07-05 23:22:57,303 - main - INFO - ==================================================
2025-07-05 23:22:57,303 - uvicorn.error - INFO - Started server process [10248]
2025-07-05 23:22:57,303 - uvicorn.error - INFO - Waiting for application startup.
2025-07-05 23:22:57,303 - uvicorn.error - INFO - Application startup complete.
2025-07-05 23:22:57,303 - uvicorn.error - INFO - Uvicorn running on http://0.0.0.0:8080 (Press CTRL+C to quit)
2025-07-05 23:22:59,249 - main - INFO - 收到飞书请求，document_id=KExEdM3URoe4JdxRyU6cduwHnZd
2025-07-05 23:22:59,820 - httpx - INFO - HTTP Request: GET https://open.feishu.cn/open-apis/docx/v1/documents/KExEdM3URoe4JdxRyU6cduwHnZd/blocks?limit=100 "HTTP/1.1 200 OK"
2025-07-05 23:23:00,378 - httpx - INFO - HTTP Request: GET https://open.feishu.cn/open-apis/drive/v1/medias/batch_get_tmp_download_url?file_tokens=SZPlbksxNo9q2AxkE3TcDp3gnlb "HTTP/1.1 200 OK"
2025-07-05 23:23:00,828 - httpx - INFO - HTTP Request: GET https://open.feishu.cn/open-apis/drive/v1/medias/batch_get_tmp_download_url?file_tokens=JqINbXfOlofwdHxsaYecenlsnAh "HTTP/1.1 200 OK"
2025-07-05 23:23:01,390 - httpx - INFO - HTTP Request: GET https://open.feishu.cn/open-apis/drive/v1/medias/batch_get_tmp_download_url?file_tokens=ZPq4buihSoeZrCxt6jQcMli8n2f "HTTP/1.1 200 OK"
2025-07-05 23:23:01,913 - httpx - INFO - HTTP Request: GET https://open.feishu.cn/open-apis/drive/v1/medias/batch_get_tmp_download_url?file_tokens=I69ubTn76oLpwRxLIP6cjz0tnWb "HTTP/1.1 200 OK"
2025-07-05 23:23:02,476 - httpx - INFO - HTTP Request: GET https://open.feishu.cn/open-apis/drive/v1/medias/batch_get_tmp_download_url?file_tokens=G7hCbfD1UoCXnwxK0hIcXbqhnPg "HTTP/1.1 200 OK"
2025-07-05 23:23:03,092 - httpx - INFO - HTTP Request: GET https://open.feishu.cn/open-apis/drive/v1/medias/batch_get_tmp_download_url?file_tokens=M5XibpflfokO3Dx25UQcS4zgnVh "HTTP/1.1 200 OK"
2025-07-05 23:23:03,094 - main - INFO - 提取的 PRD 文本:
# B端产品登录功能需求文档范文

### 1.1 功能概述

#### 1.1.1 业务流程图

![image](https://internal-api-drive-stream.feishu.cn/space/api/box/stream/download/authcode/?code=MjE0YTAzM2NkM2U2YWRjMTQ3NjIxZjQ0YmZjNTFlMTVfZjYzNTMyY2JhYjkzYjc1Y2JhMjAwYWY5YjllMTQxYTVfSUQ6NzUyMDQ4MjE0MTQwNzYwODgzNV8xNzUxNzI4OTgxOjE3NTE4MTUzODFfVjM)

#### 1.1.2 功能架构

![image](https://internal-api-drive-stream.feishu.cn/space/api/box/stream/download/authcode/?code=OWVmODBkODVlMTBjMzQ5NjZlOTExNWZiMTM0ZWQ4OTRfNmEyNjgzMzY3M2MxMTgwOTg2Y2UyZDU0ZDg4OTBmMDdfSUQ6NzUyMTgwNjA4OTg5MDEwMzI5N18xNzUxNzI4OTgxOjE3NTE4MTUzODFfVjM)

### 1.2 功能说明

#### 1.2.1 账号登录

##### 1.2.1.1 业务流程

用户打开登录网址进入登录页面；

输入登录账号、密码、验证码进行登录；

##### 1.2.1.2 页面原型

![image](https://internal-api-drive-stream.feishu.cn/space/api/box/stream/download/authcode/?code=OWJhMmQxOWNlYzA4NmNkZjM5OWY0YjU4YzYzMzZjMGNfYjU3MDgyNTMzMGRhYmVmZjdmZWI2MWY3YTRlMDc1YTBfSUQ6NzUyMDQ4MjE0MTE3MjQ5ODQzNV8xNzUxNzI4OTgyOjE3NTE4MTUzODJfVjM)

##### 1.2.1.3 逻辑说明

账号输入框：输入账号后显示清空操作按钮，点击清空按钮清空已输入的账号；

密码输入框：输入密码后显示密码明文查看按钮及清空按钮，鼠标按下明文查看按钮密码明文展示，鼠标松开后密文展示，点击清空按钮清空已输入密码；

验证码：验证码为4位随机的大写英文字母，单击验证码展示区域刷新验证码，验证码有效期为60秒；

所有输入框获取焦点时提示文字消失且边框变为绿色，失去焦点时恢复原状；

【登录】按钮：点击【登录】按钮时依次校验登录账号、密码、验证码，若某一项校验出问题则在对应输入框下方红字提醒用户错误原因，全部校验通过则成功登录并进入系统首页；

【找回密码】按钮：点击【找回密码】按钮跳转至找回密码页面；

账号首次成功登录时弹窗提示账号首次登录时需修改初始密码，点击【确定】按钮跳转至修改初始密码页面，初始密码修改后需要重新输入账号、密码、验证码进行登录；

#### 1.2.2 重置初始密码

##### 1.2.2.1 业务流程

用户初次成功登录账号后弹窗提示用户修改初始密码；

点击弹窗的【确定】按钮后页面跳转至重置初始密码页面；

##### 1.2.2.2 页面原型

![image](https://internal-api-drive-stream.feishu.cn/space/api/box/stream/download/authcode/?code=MTA0NmU0OGRmMTMwMTM2ZDc3NzI0ZGMwODM1OTQzMGZfZWY0NjI3ZjZlNjUzYzVhMTJiOTRlZWQ4M2RlNWQyN2FfSUQ6NzUyMDQ4MjE0MDI2MTgyNjU3OV8xNzUxNzI4OTgyOjE3NTE4MTUzODJfVjM)

##### 1.2.2.3 业务逻辑

新密码输入框：输入密码后显示密码明文查看按钮及清空按钮，鼠标按下明文查看按钮密码明文展示，鼠标松开后密文展示，点击清空按钮清空已输入密码；

确认密码：输入密码后显示密码明文查看按钮及清空按钮，鼠标按下明文查看按钮密码明文展示，鼠标松开后密文展示，点击清空按钮清空已输入密码；

验证码：点击【获取验证码】按钮向登录账号绑定手机号发送6位随机数字验证码，验证码已发送后【获取验证码】按钮展示60秒倒计时，倒计时结束后恢复原状，验证码有效期为60秒；

所有输入框获取焦点时提示文字消失且输入框边框变为绿色，失去焦点时恢复原状；

【取消】按钮：点击【取消】按钮取消修改初始密码，返回至登录页面；

【提交】按钮：点击【提交】按钮依次校验密码、验证码，若某一项校验出问题则在对应输入框下方红字提醒用户错误原因，全部校验通过则提示重置密码成功，然后返回至登录页面；

#### 1.2.3 找回密码

##### 1.2.3.1 业务流程

用户打开登录网址进入登录页面；

忘记登录密码后在登录页面页面点击【找回密码】按钮进入找回密码页面；

##### 1.2.3.2 页面原型

![image](https://internal-api-drive-stream.feishu.cn/space/api/box/stream/download/authcode/?code=ZTViMDZkMDQ4ZjBmYTdjMzNiM2YwMmIzM2M2ZjA2MGZfMzliMDM5MzYzYWI4YmUwZmRiOWI3ZGNiOGUwMDI5MTJfSUQ6NzUyMDQ4MjEzODAwMjA5NjE1Nl8xNzUxNzI4OTgzOjE3NTE4MTUzODNfVjM)

##### 1.2.3.3 业务逻辑

新密码输入框：输入密码后显示密码明文查看按钮及清空按钮，鼠标按下明文查看按钮密码明文展示，鼠标松开后密文展示，点击清空按钮清空已输入密码；

确认密码：输入密码后显示密码明文查看按钮及清空按钮，鼠标按下明文查看按钮密码明文展示，鼠标松开后密文展示，点击清空按钮清空已输入密码；

验证码：点击【获取验证码】按钮向登录账号绑定手机号发送6位随机数字验证码，验证码已发送后【获取验证码】按钮展示60秒倒计时，倒计时结束后恢复原状，验证码有效期为60秒；

所有输入框获取焦点时提示文字消失且输入框边框变为绿色，失去焦点时恢复原状；

【取消】按钮：点击【取消】按钮取消修改初始密码，返回至登录页面；

【提交】按钮：点击【提交】按钮依次校验密码、验证码，若某一项校验出问题则在对应输入框下方红字提醒用户错误原因，全部校验通过则提示重置密码成功，然后返回至登录页面；

#### 1.2.4 修改密码

##### 1.2.4.1 业务流程

用户成功登录账号；

在我的页面选择修改密码进入修改密码页面；

##### 1.2.4.2 页面原型

![image](https://internal-api-drive-stream.feishu.cn/space/api/box/stream/download/authcode/?code=OWViNjBlYzg1Nzg4YjI2MTcxMmVkMTVlYjg1YzMxYTFfMDM2YjY1YWJlMTkzODgwZGI1YjExYzAxNDM3ZmJhM2FfSUQ6NzUyMDQ4MjEzOTQ4MjYxOTkzMl8xNzUxNzI4OTgzOjE3NTE4MTUzODNfVjM)

##### 1.2.4.3 业务逻辑

原密码输入框：输入密码后显示密码明文查看按钮及清空按钮，鼠标按下明文查看按钮密码明文展示，鼠标松开后密文展示，点击清空按钮清空已输入密码；

新密码输入框：输入密码后显示密码明文查看按钮及清空按钮，鼠标按下明文查看按钮密码明文展示，鼠标松开后密文展示，点击清空按钮清空已输入密码；

确认密码：输入密码后显示密码明文查看按钮及清空按钮，鼠标按下明文查看按钮密码明文展示，鼠标松开后密文展示，点击清空按钮清空已输入密码；

验证码：点击【获取验证码】按钮向登录账号绑定手机号发送6位随机数字验证码，验证码已发送后【获取验证码】按钮展示60秒倒计时，倒计时结束后恢复原状，验证码有效期为60秒；

所有输入框获取焦点时提示文字消失且输入框边框变为绿色，失去焦点时恢复原状；

【取消】按钮：点击【取消】按钮取消修改密码，返回至我的页面；

【提交】按钮：点击【提交】按钮依次校验密码、验证码，若某一项校验出问题则在对应输入框下方红字提醒用户错误原因，全部校验通过则提示重置密码成功；


2025-07-05 23:23:03,097 - main - INFO - 开始调用图谱生成测试用例
2025-07-05 23:23:03,109 - langgraph_use2 - INFO - [Step 1] 尝试直接从 PRD 文本提取标题
2025-07-05 23:23:03,110 - langgraph_use2 - INFO - [Step 1] 提取标题成功: B端产品登录功能需求文档范文
2025-07-05 23:23:03,110 - langgraph_use2 - INFO - [Step 2] 提取测试点
2025-07-05 23:24:59,345 - httpx - INFO - HTTP Request: POST https://ark.cn-beijing.volces.com/api/v3/chat/completions "HTTP/1.1 200 OK"
2025-07-05 23:24:59,348 - langgraph_use2 - INFO - [Step 3] 优化测试点
2025-07-05 23:25:15,972 - httpx - INFO - HTTP Request: POST https://ark.cn-beijing.volces.com/api/v3/chat/completions "HTTP/1.1 200 OK"
2025-07-05 23:25:15,973 - langgraph_use2 - INFO - [Step 4] 生成测试用例
2025-07-05 23:25:15,973 - langgraph_use2 - INFO - 生成第 1 个用例，第 1 次尝试
2025-07-05 23:25:15,974 - langgraph_use2 - WARNING - 第 1 个测试点失败（第 1 次）: call_model2() got an unexpected keyword argument 'max_tokens'
Traceback (most recent call last):
  File "D:\pythonProject\generateTestCases\langgraph_use2.py", line 122, in generate_case
    resp = await call_model2(prompt, max_tokens=800)
                 ^^^^^^^^^^^^^^^^^^^^^^^^^^^^^^^^^^^
TypeError: call_model2() got an unexpected keyword argument 'max_tokens'

2025-07-05 23:25:15,974 - langgraph_use2 - INFO - 生成第 2 个用例，第 1 次尝试
2025-07-05 23:25:15,974 - langgraph_use2 - WARNING - 第 2 个测试点失败（第 1 次）: call_model2() got an unexpected keyword argument 'max_tokens'
Traceback (most recent call last):
  File "D:\pythonProject\generateTestCases\langgraph_use2.py", line 122, in generate_case
    resp = await call_model2(prompt, max_tokens=800)
                 ^^^^^^^^^^^^^^^^^^^^^^^^^^^^^^^^^^^
TypeError: call_model2() got an unexpected keyword argument 'max_tokens'

2025-07-05 23:25:15,974 - langgraph_use2 - INFO - 生成第 3 个用例，第 1 次尝试
2025-07-05 23:25:15,975 - langgraph_use2 - WARNING - 第 3 个测试点失败（第 1 次）: call_model2() got an unexpected keyword argument 'max_tokens'
Traceback (most recent call last):
  File "D:\pythonProject\generateTestCases\langgraph_use2.py", line 122, in generate_case
    resp = await call_model2(prompt, max_tokens=800)
                 ^^^^^^^^^^^^^^^^^^^^^^^^^^^^^^^^^^^
TypeError: call_model2() got an unexpected keyword argument 'max_tokens'

2025-07-05 23:25:15,975 - langgraph_use2 - INFO - 生成第 4 个用例，第 1 次尝试
2025-07-05 23:25:15,975 - langgraph_use2 - WARNING - 第 4 个测试点失败（第 1 次）: call_model2() got an unexpected keyword argument 'max_tokens'
Traceback (most recent call last):
  File "D:\pythonProject\generateTestCases\langgraph_use2.py", line 122, in generate_case
    resp = await call_model2(prompt, max_tokens=800)
                 ^^^^^^^^^^^^^^^^^^^^^^^^^^^^^^^^^^^
TypeError: call_model2() got an unexpected keyword argument 'max_tokens'

2025-07-05 23:25:15,975 - langgraph_use2 - INFO - 生成第 5 个用例，第 1 次尝试
2025-07-05 23:25:15,975 - langgraph_use2 - WARNING - 第 5 个测试点失败（第 1 次）: call_model2() got an unexpected keyword argument 'max_tokens'
Traceback (most recent call last):
  File "D:\pythonProject\generateTestCases\langgraph_use2.py", line 122, in generate_case
    resp = await call_model2(prompt, max_tokens=800)
                 ^^^^^^^^^^^^^^^^^^^^^^^^^^^^^^^^^^^
TypeError: call_model2() got an unexpected keyword argument 'max_tokens'

2025-07-05 23:25:15,975 - langgraph_use2 - INFO - 生成第 6 个用例，第 1 次尝试
2025-07-05 23:25:15,976 - langgraph_use2 - WARNING - 第 6 个测试点失败（第 1 次）: call_model2() got an unexpected keyword argument 'max_tokens'
Traceback (most recent call last):
  File "D:\pythonProject\generateTestCases\langgraph_use2.py", line 122, in generate_case
    resp = await call_model2(prompt, max_tokens=800)
                 ^^^^^^^^^^^^^^^^^^^^^^^^^^^^^^^^^^^
TypeError: call_model2() got an unexpected keyword argument 'max_tokens'

2025-07-05 23:25:15,976 - langgraph_use2 - INFO - 生成第 7 个用例，第 1 次尝试
2025-07-05 23:25:15,976 - langgraph_use2 - WARNING - 第 7 个测试点失败（第 1 次）: call_model2() got an unexpected keyword argument 'max_tokens'
Traceback (most recent call last):
  File "D:\pythonProject\generateTestCases\langgraph_use2.py", line 122, in generate_case
    resp = await call_model2(prompt, max_tokens=800)
                 ^^^^^^^^^^^^^^^^^^^^^^^^^^^^^^^^^^^
TypeError: call_model2() got an unexpected keyword argument 'max_tokens'

2025-07-05 23:25:15,976 - langgraph_use2 - INFO - 生成第 8 个用例，第 1 次尝试
2025-07-05 23:25:15,976 - langgraph_use2 - WARNING - 第 8 个测试点失败（第 1 次）: call_model2() got an unexpected keyword argument 'max_tokens'
Traceback (most recent call last):
  File "D:\pythonProject\generateTestCases\langgraph_use2.py", line 122, in generate_case
    resp = await call_model2(prompt, max_tokens=800)
                 ^^^^^^^^^^^^^^^^^^^^^^^^^^^^^^^^^^^
TypeError: call_model2() got an unexpected keyword argument 'max_tokens'

2025-07-05 23:25:15,976 - langgraph_use2 - INFO - 生成第 9 个用例，第 1 次尝试
2025-07-05 23:25:15,976 - langgraph_use2 - WARNING - 第 9 个测试点失败（第 1 次）: call_model2() got an unexpected keyword argument 'max_tokens'
Traceback (most recent call last):
  File "D:\pythonProject\generateTestCases\langgraph_use2.py", line 122, in generate_case
    resp = await call_model2(prompt, max_tokens=800)
                 ^^^^^^^^^^^^^^^^^^^^^^^^^^^^^^^^^^^
TypeError: call_model2() got an unexpected keyword argument 'max_tokens'

2025-07-05 23:25:15,976 - langgraph_use2 - INFO - 生成第 10 个用例，第 1 次尝试
2025-07-05 23:25:15,976 - langgraph_use2 - WARNING - 第 10 个测试点失败（第 1 次）: call_model2() got an unexpected keyword argument 'max_tokens'
Traceback (most recent call last):
  File "D:\pythonProject\generateTestCases\langgraph_use2.py", line 122, in generate_case
    resp = await call_model2(prompt, max_tokens=800)
                 ^^^^^^^^^^^^^^^^^^^^^^^^^^^^^^^^^^^
TypeError: call_model2() got an unexpected keyword argument 'max_tokens'

2025-07-05 23:25:15,977 - langgraph_use2 - INFO - 生成第 11 个用例，第 1 次尝试
2025-07-05 23:25:15,977 - langgraph_use2 - WARNING - 第 11 个测试点失败（第 1 次）: call_model2() got an unexpected keyword argument 'max_tokens'
Traceback (most recent call last):
  File "D:\pythonProject\generateTestCases\langgraph_use2.py", line 122, in generate_case
    resp = await call_model2(prompt, max_tokens=800)
                 ^^^^^^^^^^^^^^^^^^^^^^^^^^^^^^^^^^^
TypeError: call_model2() got an unexpected keyword argument 'max_tokens'

2025-07-05 23:25:15,977 - langgraph_use2 - INFO - 生成第 12 个用例，第 1 次尝试
2025-07-05 23:25:15,977 - langgraph_use2 - WARNING - 第 12 个测试点失败（第 1 次）: call_model2() got an unexpected keyword argument 'max_tokens'
Traceback (most recent call last):
  File "D:\pythonProject\generateTestCases\langgraph_use2.py", line 122, in generate_case
    resp = await call_model2(prompt, max_tokens=800)
                 ^^^^^^^^^^^^^^^^^^^^^^^^^^^^^^^^^^^
TypeError: call_model2() got an unexpected keyword argument 'max_tokens'

2025-07-05 23:25:15,977 - langgraph_use2 - INFO - 生成第 13 个用例，第 1 次尝试
2025-07-05 23:25:15,977 - langgraph_use2 - WARNING - 第 13 个测试点失败（第 1 次）: call_model2() got an unexpected keyword argument 'max_tokens'
Traceback (most recent call last):
  File "D:\pythonProject\generateTestCases\langgraph_use2.py", line 122, in generate_case
    resp = await call_model2(prompt, max_tokens=800)
                 ^^^^^^^^^^^^^^^^^^^^^^^^^^^^^^^^^^^
TypeError: call_model2() got an unexpected keyword argument 'max_tokens'

2025-07-05 23:25:15,978 - langgraph_use2 - INFO - 生成第 14 个用例，第 1 次尝试
2025-07-05 23:25:15,978 - langgraph_use2 - WARNING - 第 14 个测试点失败（第 1 次）: call_model2() got an unexpected keyword argument 'max_tokens'
Traceback (most recent call last):
  File "D:\pythonProject\generateTestCases\langgraph_use2.py", line 122, in generate_case
    resp = await call_model2(prompt, max_tokens=800)
                 ^^^^^^^^^^^^^^^^^^^^^^^^^^^^^^^^^^^
TypeError: call_model2() got an unexpected keyword argument 'max_tokens'

2025-07-05 23:25:15,978 - langgraph_use2 - INFO - 生成第 15 个用例，第 1 次尝试
2025-07-05 23:25:15,978 - langgraph_use2 - WARNING - 第 15 个测试点失败（第 1 次）: call_model2() got an unexpected keyword argument 'max_tokens'
Traceback (most recent call last):
  File "D:\pythonProject\generateTestCases\langgraph_use2.py", line 122, in generate_case
    resp = await call_model2(prompt, max_tokens=800)
                 ^^^^^^^^^^^^^^^^^^^^^^^^^^^^^^^^^^^
TypeError: call_model2() got an unexpected keyword argument 'max_tokens'

2025-07-05 23:25:15,978 - langgraph_use2 - INFO - 生成第 16 个用例，第 1 次尝试
2025-07-05 23:25:15,978 - langgraph_use2 - WARNING - 第 16 个测试点失败（第 1 次）: call_model2() got an unexpected keyword argument 'max_tokens'
Traceback (most recent call last):
  File "D:\pythonProject\generateTestCases\langgraph_use2.py", line 122, in generate_case
    resp = await call_model2(prompt, max_tokens=800)
                 ^^^^^^^^^^^^^^^^^^^^^^^^^^^^^^^^^^^
TypeError: call_model2() got an unexpected keyword argument 'max_tokens'

2025-07-05 23:25:15,978 - langgraph_use2 - INFO - 生成第 17 个用例，第 1 次尝试
2025-07-05 23:25:15,978 - langgraph_use2 - WARNING - 第 17 个测试点失败（第 1 次）: call_model2() got an unexpected keyword argument 'max_tokens'
Traceback (most recent call last):
  File "D:\pythonProject\generateTestCases\langgraph_use2.py", line 122, in generate_case
    resp = await call_model2(prompt, max_tokens=800)
                 ^^^^^^^^^^^^^^^^^^^^^^^^^^^^^^^^^^^
TypeError: call_model2() got an unexpected keyword argument 'max_tokens'

2025-07-05 23:25:15,978 - langgraph_use2 - INFO - 生成第 18 个用例，第 1 次尝试
2025-07-05 23:25:15,979 - langgraph_use2 - WARNING - 第 18 个测试点失败（第 1 次）: call_model2() got an unexpected keyword argument 'max_tokens'
Traceback (most recent call last):
  File "D:\pythonProject\generateTestCases\langgraph_use2.py", line 122, in generate_case
    resp = await call_model2(prompt, max_tokens=800)
                 ^^^^^^^^^^^^^^^^^^^^^^^^^^^^^^^^^^^
TypeError: call_model2() got an unexpected keyword argument 'max_tokens'

2025-07-05 23:25:15,979 - langgraph_use2 - INFO - 生成第 19 个用例，第 1 次尝试
2025-07-05 23:25:15,979 - langgraph_use2 - WARNING - 第 19 个测试点失败（第 1 次）: call_model2() got an unexpected keyword argument 'max_tokens'
Traceback (most recent call last):
  File "D:\pythonProject\generateTestCases\langgraph_use2.py", line 122, in generate_case
    resp = await call_model2(prompt, max_tokens=800)
                 ^^^^^^^^^^^^^^^^^^^^^^^^^^^^^^^^^^^
TypeError: call_model2() got an unexpected keyword argument 'max_tokens'

2025-07-05 23:25:15,979 - langgraph_use2 - INFO - 生成第 20 个用例，第 1 次尝试
2025-07-05 23:25:15,979 - langgraph_use2 - WARNING - 第 20 个测试点失败（第 1 次）: call_model2() got an unexpected keyword argument 'max_tokens'
Traceback (most recent call last):
  File "D:\pythonProject\generateTestCases\langgraph_use2.py", line 122, in generate_case
    resp = await call_model2(prompt, max_tokens=800)
                 ^^^^^^^^^^^^^^^^^^^^^^^^^^^^^^^^^^^
TypeError: call_model2() got an unexpected keyword argument 'max_tokens'

2025-07-05 23:25:15,979 - langgraph_use2 - INFO - 生成第 21 个用例，第 1 次尝试
2025-07-05 23:25:15,979 - langgraph_use2 - WARNING - 第 21 个测试点失败（第 1 次）: call_model2() got an unexpected keyword argument 'max_tokens'
Traceback (most recent call last):
  File "D:\pythonProject\generateTestCases\langgraph_use2.py", line 122, in generate_case
    resp = await call_model2(prompt, max_tokens=800)
                 ^^^^^^^^^^^^^^^^^^^^^^^^^^^^^^^^^^^
TypeError: call_model2() got an unexpected keyword argument 'max_tokens'

2025-07-05 23:25:15,980 - langgraph_use2 - INFO - 生成第 22 个用例，第 1 次尝试
2025-07-05 23:25:15,980 - langgraph_use2 - WARNING - 第 22 个测试点失败（第 1 次）: call_model2() got an unexpected keyword argument 'max_tokens'
Traceback (most recent call last):
  File "D:\pythonProject\generateTestCases\langgraph_use2.py", line 122, in generate_case
    resp = await call_model2(prompt, max_tokens=800)
                 ^^^^^^^^^^^^^^^^^^^^^^^^^^^^^^^^^^^
TypeError: call_model2() got an unexpected keyword argument 'max_tokens'

2025-07-05 23:25:15,980 - langgraph_use2 - INFO - 生成第 23 个用例，第 1 次尝试
2025-07-05 23:25:15,980 - langgraph_use2 - WARNING - 第 23 个测试点失败（第 1 次）: call_model2() got an unexpected keyword argument 'max_tokens'
Traceback (most recent call last):
  File "D:\pythonProject\generateTestCases\langgraph_use2.py", line 122, in generate_case
    resp = await call_model2(prompt, max_tokens=800)
                 ^^^^^^^^^^^^^^^^^^^^^^^^^^^^^^^^^^^
TypeError: call_model2() got an unexpected keyword argument 'max_tokens'

2025-07-05 23:25:15,980 - langgraph_use2 - INFO - 生成第 24 个用例，第 1 次尝试
2025-07-05 23:25:15,980 - langgraph_use2 - WARNING - 第 24 个测试点失败（第 1 次）: call_model2() got an unexpected keyword argument 'max_tokens'
Traceback (most recent call last):
  File "D:\pythonProject\generateTestCases\langgraph_use2.py", line 122, in generate_case
    resp = await call_model2(prompt, max_tokens=800)
                 ^^^^^^^^^^^^^^^^^^^^^^^^^^^^^^^^^^^
TypeError: call_model2() got an unexpected keyword argument 'max_tokens'

2025-07-05 23:25:15,981 - langgraph_use2 - INFO - 生成第 25 个用例，第 1 次尝试
2025-07-05 23:25:15,981 - langgraph_use2 - WARNING - 第 25 个测试点失败（第 1 次）: call_model2() got an unexpected keyword argument 'max_tokens'
Traceback (most recent call last):
  File "D:\pythonProject\generateTestCases\langgraph_use2.py", line 122, in generate_case
    resp = await call_model2(prompt, max_tokens=800)
                 ^^^^^^^^^^^^^^^^^^^^^^^^^^^^^^^^^^^
TypeError: call_model2() got an unexpected keyword argument 'max_tokens'

2025-07-05 23:25:15,981 - langgraph_use2 - INFO - 生成第 26 个用例，第 1 次尝试
2025-07-05 23:25:15,981 - langgraph_use2 - WARNING - 第 26 个测试点失败（第 1 次）: call_model2() got an unexpected keyword argument 'max_tokens'
Traceback (most recent call last):
  File "D:\pythonProject\generateTestCases\langgraph_use2.py", line 122, in generate_case
    resp = await call_model2(prompt, max_tokens=800)
                 ^^^^^^^^^^^^^^^^^^^^^^^^^^^^^^^^^^^
TypeError: call_model2() got an unexpected keyword argument 'max_tokens'

2025-07-05 23:25:15,981 - langgraph_use2 - INFO - 生成第 27 个用例，第 1 次尝试
2025-07-05 23:25:15,982 - langgraph_use2 - WARNING - 第 27 个测试点失败（第 1 次）: call_model2() got an unexpected keyword argument 'max_tokens'
Traceback (most recent call last):
  File "D:\pythonProject\generateTestCases\langgraph_use2.py", line 122, in generate_case
    resp = await call_model2(prompt, max_tokens=800)
                 ^^^^^^^^^^^^^^^^^^^^^^^^^^^^^^^^^^^
TypeError: call_model2() got an unexpected keyword argument 'max_tokens'

2025-07-05 23:25:16,992 - langgraph_use2 - INFO - 生成第 1 个用例，第 2 次尝试
2025-07-05 23:25:16,993 - langgraph_use2 - WARNING - 第 1 个测试点失败（第 2 次）: call_model2() got an unexpected keyword argument 'max_tokens'
Traceback (most recent call last):
  File "D:\pythonProject\generateTestCases\langgraph_use2.py", line 122, in generate_case
    resp = await call_model2(prompt, max_tokens=800)
                 ^^^^^^^^^^^^^^^^^^^^^^^^^^^^^^^^^^^
TypeError: call_model2() got an unexpected keyword argument 'max_tokens'

2025-07-05 23:25:16,993 - langgraph_use2 - INFO - 生成第 5 个用例，第 2 次尝试
2025-07-05 23:25:16,993 - langgraph_use2 - WARNING - 第 5 个测试点失败（第 2 次）: call_model2() got an unexpected keyword argument 'max_tokens'
Traceback (most recent call last):
  File "D:\pythonProject\generateTestCases\langgraph_use2.py", line 122, in generate_case
    resp = await call_model2(prompt, max_tokens=800)
                 ^^^^^^^^^^^^^^^^^^^^^^^^^^^^^^^^^^^
TypeError: call_model2() got an unexpected keyword argument 'max_tokens'

2025-07-05 23:25:16,993 - langgraph_use2 - INFO - 生成第 12 个用例，第 2 次尝试
2025-07-05 23:25:16,993 - langgraph_use2 - WARNING - 第 12 个测试点失败（第 2 次）: call_model2() got an unexpected keyword argument 'max_tokens'
Traceback (most recent call last):
  File "D:\pythonProject\generateTestCases\langgraph_use2.py", line 122, in generate_case
    resp = await call_model2(prompt, max_tokens=800)
                 ^^^^^^^^^^^^^^^^^^^^^^^^^^^^^^^^^^^
TypeError: call_model2() got an unexpected keyword argument 'max_tokens'

2025-07-05 23:25:16,994 - langgraph_use2 - INFO - 生成第 13 个用例，第 2 次尝试
2025-07-05 23:25:16,994 - langgraph_use2 - WARNING - 第 13 个测试点失败（第 2 次）: call_model2() got an unexpected keyword argument 'max_tokens'
Traceback (most recent call last):
  File "D:\pythonProject\generateTestCases\langgraph_use2.py", line 122, in generate_case
    resp = await call_model2(prompt, max_tokens=800)
                 ^^^^^^^^^^^^^^^^^^^^^^^^^^^^^^^^^^^
TypeError: call_model2() got an unexpected keyword argument 'max_tokens'

2025-07-05 23:25:16,994 - langgraph_use2 - INFO - 生成第 27 个用例，第 2 次尝试
2025-07-05 23:25:16,994 - langgraph_use2 - WARNING - 第 27 个测试点失败（第 2 次）: call_model2() got an unexpected keyword argument 'max_tokens'
Traceback (most recent call last):
  File "D:\pythonProject\generateTestCases\langgraph_use2.py", line 122, in generate_case
    resp = await call_model2(prompt, max_tokens=800)
                 ^^^^^^^^^^^^^^^^^^^^^^^^^^^^^^^^^^^
TypeError: call_model2() got an unexpected keyword argument 'max_tokens'

2025-07-05 23:25:16,994 - langgraph_use2 - INFO - 生成第 26 个用例，第 2 次尝试
2025-07-05 23:25:16,994 - langgraph_use2 - WARNING - 第 26 个测试点失败（第 2 次）: call_model2() got an unexpected keyword argument 'max_tokens'
Traceback (most recent call last):
  File "D:\pythonProject\generateTestCases\langgraph_use2.py", line 122, in generate_case
    resp = await call_model2(prompt, max_tokens=800)
                 ^^^^^^^^^^^^^^^^^^^^^^^^^^^^^^^^^^^
TypeError: call_model2() got an unexpected keyword argument 'max_tokens'

2025-07-05 23:25:16,995 - langgraph_use2 - INFO - 生成第 25 个用例，第 2 次尝试
2025-07-05 23:25:16,995 - langgraph_use2 - WARNING - 第 25 个测试点失败（第 2 次）: call_model2() got an unexpected keyword argument 'max_tokens'
Traceback (most recent call last):
  File "D:\pythonProject\generateTestCases\langgraph_use2.py", line 122, in generate_case
    resp = await call_model2(prompt, max_tokens=800)
                 ^^^^^^^^^^^^^^^^^^^^^^^^^^^^^^^^^^^
TypeError: call_model2() got an unexpected keyword argument 'max_tokens'

2025-07-05 23:25:16,995 - langgraph_use2 - INFO - 生成第 24 个用例，第 2 次尝试
2025-07-05 23:25:16,995 - langgraph_use2 - WARNING - 第 24 个测试点失败（第 2 次）: call_model2() got an unexpected keyword argument 'max_tokens'
Traceback (most recent call last):
  File "D:\pythonProject\generateTestCases\langgraph_use2.py", line 122, in generate_case
    resp = await call_model2(prompt, max_tokens=800)
                 ^^^^^^^^^^^^^^^^^^^^^^^^^^^^^^^^^^^
TypeError: call_model2() got an unexpected keyword argument 'max_tokens'

2025-07-05 23:25:16,998 - langgraph_use2 - INFO - 生成第 23 个用例，第 2 次尝试
2025-07-05 23:25:16,998 - langgraph_use2 - WARNING - 第 23 个测试点失败（第 2 次）: call_model2() got an unexpected keyword argument 'max_tokens'
Traceback (most recent call last):
  File "D:\pythonProject\generateTestCases\langgraph_use2.py", line 122, in generate_case
    resp = await call_model2(prompt, max_tokens=800)
                 ^^^^^^^^^^^^^^^^^^^^^^^^^^^^^^^^^^^
TypeError: call_model2() got an unexpected keyword argument 'max_tokens'

2025-07-05 23:25:16,998 - langgraph_use2 - INFO - 生成第 22 个用例，第 2 次尝试
2025-07-05 23:25:16,999 - langgraph_use2 - WARNING - 第 22 个测试点失败（第 2 次）: call_model2() got an unexpected keyword argument 'max_tokens'
Traceback (most recent call last):
  File "D:\pythonProject\generateTestCases\langgraph_use2.py", line 122, in generate_case
    resp = await call_model2(prompt, max_tokens=800)
                 ^^^^^^^^^^^^^^^^^^^^^^^^^^^^^^^^^^^
TypeError: call_model2() got an unexpected keyword argument 'max_tokens'

2025-07-05 23:25:16,999 - langgraph_use2 - INFO - 生成第 21 个用例，第 2 次尝试
2025-07-05 23:25:16,999 - langgraph_use2 - WARNING - 第 21 个测试点失败（第 2 次）: call_model2() got an unexpected keyword argument 'max_tokens'
Traceback (most recent call last):
  File "D:\pythonProject\generateTestCases\langgraph_use2.py", line 122, in generate_case
    resp = await call_model2(prompt, max_tokens=800)
                 ^^^^^^^^^^^^^^^^^^^^^^^^^^^^^^^^^^^
TypeError: call_model2() got an unexpected keyword argument 'max_tokens'

2025-07-05 23:25:16,999 - langgraph_use2 - INFO - 生成第 20 个用例，第 2 次尝试
2025-07-05 23:25:16,999 - langgraph_use2 - WARNING - 第 20 个测试点失败（第 2 次）: call_model2() got an unexpected keyword argument 'max_tokens'
Traceback (most recent call last):
  File "D:\pythonProject\generateTestCases\langgraph_use2.py", line 122, in generate_case
    resp = await call_model2(prompt, max_tokens=800)
                 ^^^^^^^^^^^^^^^^^^^^^^^^^^^^^^^^^^^
TypeError: call_model2() got an unexpected keyword argument 'max_tokens'

2025-07-05 23:25:16,999 - langgraph_use2 - INFO - 生成第 19 个用例，第 2 次尝试
2025-07-05 23:25:16,999 - langgraph_use2 - WARNING - 第 19 个测试点失败（第 2 次）: call_model2() got an unexpected keyword argument 'max_tokens'
Traceback (most recent call last):
  File "D:\pythonProject\generateTestCases\langgraph_use2.py", line 122, in generate_case
    resp = await call_model2(prompt, max_tokens=800)
                 ^^^^^^^^^^^^^^^^^^^^^^^^^^^^^^^^^^^
TypeError: call_model2() got an unexpected keyword argument 'max_tokens'

2025-07-05 23:25:16,999 - langgraph_use2 - INFO - 生成第 18 个用例，第 2 次尝试
2025-07-05 23:25:17,000 - langgraph_use2 - WARNING - 第 18 个测试点失败（第 2 次）: call_model2() got an unexpected keyword argument 'max_tokens'
Traceback (most recent call last):
  File "D:\pythonProject\generateTestCases\langgraph_use2.py", line 122, in generate_case
    resp = await call_model2(prompt, max_tokens=800)
                 ^^^^^^^^^^^^^^^^^^^^^^^^^^^^^^^^^^^
TypeError: call_model2() got an unexpected keyword argument 'max_tokens'

2025-07-05 23:25:17,000 - langgraph_use2 - INFO - 生成第 17 个用例，第 2 次尝试
2025-07-05 23:25:17,000 - langgraph_use2 - WARNING - 第 17 个测试点失败（第 2 次）: call_model2() got an unexpected keyword argument 'max_tokens'
Traceback (most recent call last):
  File "D:\pythonProject\generateTestCases\langgraph_use2.py", line 122, in generate_case
    resp = await call_model2(prompt, max_tokens=800)
                 ^^^^^^^^^^^^^^^^^^^^^^^^^^^^^^^^^^^
TypeError: call_model2() got an unexpected keyword argument 'max_tokens'

2025-07-05 23:25:17,000 - langgraph_use2 - INFO - 生成第 16 个用例，第 2 次尝试
2025-07-05 23:25:17,000 - langgraph_use2 - WARNING - 第 16 个测试点失败（第 2 次）: call_model2() got an unexpected keyword argument 'max_tokens'
Traceback (most recent call last):
  File "D:\pythonProject\generateTestCases\langgraph_use2.py", line 122, in generate_case
    resp = await call_model2(prompt, max_tokens=800)
                 ^^^^^^^^^^^^^^^^^^^^^^^^^^^^^^^^^^^
TypeError: call_model2() got an unexpected keyword argument 'max_tokens'

2025-07-05 23:25:17,000 - langgraph_use2 - INFO - 生成第 15 个用例，第 2 次尝试
2025-07-05 23:25:17,000 - langgraph_use2 - WARNING - 第 15 个测试点失败（第 2 次）: call_model2() got an unexpected keyword argument 'max_tokens'
Traceback (most recent call last):
  File "D:\pythonProject\generateTestCases\langgraph_use2.py", line 122, in generate_case
    resp = await call_model2(prompt, max_tokens=800)
                 ^^^^^^^^^^^^^^^^^^^^^^^^^^^^^^^^^^^
TypeError: call_model2() got an unexpected keyword argument 'max_tokens'

2025-07-05 23:25:17,000 - langgraph_use2 - INFO - 生成第 4 个用例，第 2 次尝试
2025-07-05 23:25:17,001 - langgraph_use2 - WARNING - 第 4 个测试点失败（第 2 次）: call_model2() got an unexpected keyword argument 'max_tokens'
Traceback (most recent call last):
  File "D:\pythonProject\generateTestCases\langgraph_use2.py", line 122, in generate_case
    resp = await call_model2(prompt, max_tokens=800)
                 ^^^^^^^^^^^^^^^^^^^^^^^^^^^^^^^^^^^
TypeError: call_model2() got an unexpected keyword argument 'max_tokens'

2025-07-05 23:25:17,001 - langgraph_use2 - INFO - 生成第 11 个用例，第 2 次尝试
2025-07-05 23:25:17,001 - langgraph_use2 - WARNING - 第 11 个测试点失败（第 2 次）: call_model2() got an unexpected keyword argument 'max_tokens'
Traceback (most recent call last):
  File "D:\pythonProject\generateTestCases\langgraph_use2.py", line 122, in generate_case
    resp = await call_model2(prompt, max_tokens=800)
                 ^^^^^^^^^^^^^^^^^^^^^^^^^^^^^^^^^^^
TypeError: call_model2() got an unexpected keyword argument 'max_tokens'

2025-07-05 23:25:17,001 - langgraph_use2 - INFO - 生成第 10 个用例，第 2 次尝试
2025-07-05 23:25:17,001 - langgraph_use2 - WARNING - 第 10 个测试点失败（第 2 次）: call_model2() got an unexpected keyword argument 'max_tokens'
Traceback (most recent call last):
  File "D:\pythonProject\generateTestCases\langgraph_use2.py", line 122, in generate_case
    resp = await call_model2(prompt, max_tokens=800)
                 ^^^^^^^^^^^^^^^^^^^^^^^^^^^^^^^^^^^
TypeError: call_model2() got an unexpected keyword argument 'max_tokens'

2025-07-05 23:25:17,001 - langgraph_use2 - INFO - 生成第 9 个用例，第 2 次尝试
2025-07-05 23:25:17,001 - langgraph_use2 - WARNING - 第 9 个测试点失败（第 2 次）: call_model2() got an unexpected keyword argument 'max_tokens'
Traceback (most recent call last):
  File "D:\pythonProject\generateTestCases\langgraph_use2.py", line 122, in generate_case
    resp = await call_model2(prompt, max_tokens=800)
                 ^^^^^^^^^^^^^^^^^^^^^^^^^^^^^^^^^^^
TypeError: call_model2() got an unexpected keyword argument 'max_tokens'

2025-07-05 23:25:17,001 - langgraph_use2 - INFO - 生成第 8 个用例，第 2 次尝试
2025-07-05 23:25:17,002 - langgraph_use2 - WARNING - 第 8 个测试点失败（第 2 次）: call_model2() got an unexpected keyword argument 'max_tokens'
Traceback (most recent call last):
  File "D:\pythonProject\generateTestCases\langgraph_use2.py", line 122, in generate_case
    resp = await call_model2(prompt, max_tokens=800)
                 ^^^^^^^^^^^^^^^^^^^^^^^^^^^^^^^^^^^
TypeError: call_model2() got an unexpected keyword argument 'max_tokens'

2025-07-05 23:25:17,002 - langgraph_use2 - INFO - 生成第 7 个用例，第 2 次尝试
2025-07-05 23:25:17,002 - langgraph_use2 - WARNING - 第 7 个测试点失败（第 2 次）: call_model2() got an unexpected keyword argument 'max_tokens'
Traceback (most recent call last):
  File "D:\pythonProject\generateTestCases\langgraph_use2.py", line 122, in generate_case
    resp = await call_model2(prompt, max_tokens=800)
                 ^^^^^^^^^^^^^^^^^^^^^^^^^^^^^^^^^^^
TypeError: call_model2() got an unexpected keyword argument 'max_tokens'

2025-07-05 23:25:17,002 - langgraph_use2 - INFO - 生成第 14 个用例，第 2 次尝试
2025-07-05 23:25:17,002 - langgraph_use2 - WARNING - 第 14 个测试点失败（第 2 次）: call_model2() got an unexpected keyword argument 'max_tokens'
Traceback (most recent call last):
  File "D:\pythonProject\generateTestCases\langgraph_use2.py", line 122, in generate_case
    resp = await call_model2(prompt, max_tokens=800)
                 ^^^^^^^^^^^^^^^^^^^^^^^^^^^^^^^^^^^
TypeError: call_model2() got an unexpected keyword argument 'max_tokens'

2025-07-05 23:25:17,002 - langgraph_use2 - INFO - 生成第 2 个用例，第 2 次尝试
2025-07-05 23:25:17,003 - langgraph_use2 - WARNING - 第 2 个测试点失败（第 2 次）: call_model2() got an unexpected keyword argument 'max_tokens'
Traceback (most recent call last):
  File "D:\pythonProject\generateTestCases\langgraph_use2.py", line 122, in generate_case
    resp = await call_model2(prompt, max_tokens=800)
                 ^^^^^^^^^^^^^^^^^^^^^^^^^^^^^^^^^^^
TypeError: call_model2() got an unexpected keyword argument 'max_tokens'

2025-07-05 23:25:17,003 - langgraph_use2 - INFO - 生成第 3 个用例，第 2 次尝试
2025-07-05 23:25:17,003 - langgraph_use2 - WARNING - 第 3 个测试点失败（第 2 次）: call_model2() got an unexpected keyword argument 'max_tokens'
Traceback (most recent call last):
  File "D:\pythonProject\generateTestCases\langgraph_use2.py", line 122, in generate_case
    resp = await call_model2(prompt, max_tokens=800)
                 ^^^^^^^^^^^^^^^^^^^^^^^^^^^^^^^^^^^
TypeError: call_model2() got an unexpected keyword argument 'max_tokens'

2025-07-05 23:25:17,003 - langgraph_use2 - INFO - 生成第 6 个用例，第 2 次尝试
2025-07-05 23:25:17,003 - langgraph_use2 - WARNING - 第 6 个测试点失败（第 2 次）: call_model2() got an unexpected keyword argument 'max_tokens'
Traceback (most recent call last):
  File "D:\pythonProject\generateTestCases\langgraph_use2.py", line 122, in generate_case
    resp = await call_model2(prompt, max_tokens=800)
                 ^^^^^^^^^^^^^^^^^^^^^^^^^^^^^^^^^^^
TypeError: call_model2() got an unexpected keyword argument 'max_tokens'

2025-07-05 23:25:18,005 - langgraph_use2 - INFO - 生成第 1 个用例，第 3 次尝试
2025-07-05 23:25:18,006 - langgraph_use2 - WARNING - 第 1 个测试点失败（第 3 次）: call_model2() got an unexpected keyword argument 'max_tokens'
Traceback (most recent call last):
  File "D:\pythonProject\generateTestCases\langgraph_use2.py", line 122, in generate_case
    resp = await call_model2(prompt, max_tokens=800)
                 ^^^^^^^^^^^^^^^^^^^^^^^^^^^^^^^^^^^
TypeError: call_model2() got an unexpected keyword argument 'max_tokens'

2025-07-05 23:25:18,006 - langgraph_use2 - INFO - 生成第 27 个用例，第 3 次尝试
2025-07-05 23:25:18,006 - langgraph_use2 - WARNING - 第 27 个测试点失败（第 3 次）: call_model2() got an unexpected keyword argument 'max_tokens'
Traceback (most recent call last):
  File "D:\pythonProject\generateTestCases\langgraph_use2.py", line 122, in generate_case
    resp = await call_model2(prompt, max_tokens=800)
                 ^^^^^^^^^^^^^^^^^^^^^^^^^^^^^^^^^^^
TypeError: call_model2() got an unexpected keyword argument 'max_tokens'

2025-07-05 23:25:18,006 - langgraph_use2 - INFO - 生成第 20 个用例，第 3 次尝试
2025-07-05 23:25:18,006 - langgraph_use2 - WARNING - 第 20 个测试点失败（第 3 次）: call_model2() got an unexpected keyword argument 'max_tokens'
Traceback (most recent call last):
  File "D:\pythonProject\generateTestCases\langgraph_use2.py", line 122, in generate_case
    resp = await call_model2(prompt, max_tokens=800)
                 ^^^^^^^^^^^^^^^^^^^^^^^^^^^^^^^^^^^
TypeError: call_model2() got an unexpected keyword argument 'max_tokens'

2025-07-05 23:25:18,006 - langgraph_use2 - INFO - 生成第 19 个用例，第 3 次尝试
2025-07-05 23:25:18,007 - langgraph_use2 - WARNING - 第 19 个测试点失败（第 3 次）: call_model2() got an unexpected keyword argument 'max_tokens'
Traceback (most recent call last):
  File "D:\pythonProject\generateTestCases\langgraph_use2.py", line 122, in generate_case
    resp = await call_model2(prompt, max_tokens=800)
                 ^^^^^^^^^^^^^^^^^^^^^^^^^^^^^^^^^^^
TypeError: call_model2() got an unexpected keyword argument 'max_tokens'

2025-07-05 23:25:18,007 - langgraph_use2 - INFO - 生成第 6 个用例，第 3 次尝试
2025-07-05 23:25:18,007 - langgraph_use2 - WARNING - 第 6 个测试点失败（第 3 次）: call_model2() got an unexpected keyword argument 'max_tokens'
Traceback (most recent call last):
  File "D:\pythonProject\generateTestCases\langgraph_use2.py", line 122, in generate_case
    resp = await call_model2(prompt, max_tokens=800)
                 ^^^^^^^^^^^^^^^^^^^^^^^^^^^^^^^^^^^
TypeError: call_model2() got an unexpected keyword argument 'max_tokens'

2025-07-05 23:25:18,007 - langgraph_use2 - INFO - 生成第 3 个用例，第 3 次尝试
2025-07-05 23:25:18,007 - langgraph_use2 - WARNING - 第 3 个测试点失败（第 3 次）: call_model2() got an unexpected keyword argument 'max_tokens'
Traceback (most recent call last):
  File "D:\pythonProject\generateTestCases\langgraph_use2.py", line 122, in generate_case
    resp = await call_model2(prompt, max_tokens=800)
                 ^^^^^^^^^^^^^^^^^^^^^^^^^^^^^^^^^^^
TypeError: call_model2() got an unexpected keyword argument 'max_tokens'

2025-07-05 23:25:18,007 - langgraph_use2 - INFO - 生成第 2 个用例，第 3 次尝试
2025-07-05 23:25:18,007 - langgraph_use2 - WARNING - 第 2 个测试点失败（第 3 次）: call_model2() got an unexpected keyword argument 'max_tokens'
Traceback (most recent call last):
  File "D:\pythonProject\generateTestCases\langgraph_use2.py", line 122, in generate_case
    resp = await call_model2(prompt, max_tokens=800)
                 ^^^^^^^^^^^^^^^^^^^^^^^^^^^^^^^^^^^
TypeError: call_model2() got an unexpected keyword argument 'max_tokens'

2025-07-05 23:25:18,007 - langgraph_use2 - INFO - 生成第 14 个用例，第 3 次尝试
2025-07-05 23:25:18,008 - langgraph_use2 - WARNING - 第 14 个测试点失败（第 3 次）: call_model2() got an unexpected keyword argument 'max_tokens'
Traceback (most recent call last):
  File "D:\pythonProject\generateTestCases\langgraph_use2.py", line 122, in generate_case
    resp = await call_model2(prompt, max_tokens=800)
                 ^^^^^^^^^^^^^^^^^^^^^^^^^^^^^^^^^^^
TypeError: call_model2() got an unexpected keyword argument 'max_tokens'

2025-07-05 23:25:18,008 - langgraph_use2 - INFO - 生成第 7 个用例，第 3 次尝试
2025-07-05 23:25:18,008 - langgraph_use2 - WARNING - 第 7 个测试点失败（第 3 次）: call_model2() got an unexpected keyword argument 'max_tokens'
Traceback (most recent call last):
  File "D:\pythonProject\generateTestCases\langgraph_use2.py", line 122, in generate_case
    resp = await call_model2(prompt, max_tokens=800)
                 ^^^^^^^^^^^^^^^^^^^^^^^^^^^^^^^^^^^
TypeError: call_model2() got an unexpected keyword argument 'max_tokens'

2025-07-05 23:25:18,008 - langgraph_use2 - INFO - 生成第 8 个用例，第 3 次尝试
2025-07-05 23:25:18,008 - langgraph_use2 - WARNING - 第 8 个测试点失败（第 3 次）: call_model2() got an unexpected keyword argument 'max_tokens'
Traceback (most recent call last):
  File "D:\pythonProject\generateTestCases\langgraph_use2.py", line 122, in generate_case
    resp = await call_model2(prompt, max_tokens=800)
                 ^^^^^^^^^^^^^^^^^^^^^^^^^^^^^^^^^^^
TypeError: call_model2() got an unexpected keyword argument 'max_tokens'

2025-07-05 23:25:18,008 - langgraph_use2 - INFO - 生成第 9 个用例，第 3 次尝试
2025-07-05 23:25:18,008 - langgraph_use2 - WARNING - 第 9 个测试点失败（第 3 次）: call_model2() got an unexpected keyword argument 'max_tokens'
Traceback (most recent call last):
  File "D:\pythonProject\generateTestCases\langgraph_use2.py", line 122, in generate_case
    resp = await call_model2(prompt, max_tokens=800)
                 ^^^^^^^^^^^^^^^^^^^^^^^^^^^^^^^^^^^
TypeError: call_model2() got an unexpected keyword argument 'max_tokens'

2025-07-05 23:25:18,008 - langgraph_use2 - INFO - 生成第 10 个用例，第 3 次尝试
2025-07-05 23:25:18,008 - langgraph_use2 - WARNING - 第 10 个测试点失败（第 3 次）: call_model2() got an unexpected keyword argument 'max_tokens'
Traceback (most recent call last):
  File "D:\pythonProject\generateTestCases\langgraph_use2.py", line 122, in generate_case
    resp = await call_model2(prompt, max_tokens=800)
                 ^^^^^^^^^^^^^^^^^^^^^^^^^^^^^^^^^^^
TypeError: call_model2() got an unexpected keyword argument 'max_tokens'

2025-07-05 23:25:18,009 - langgraph_use2 - INFO - 生成第 11 个用例，第 3 次尝试
2025-07-05 23:25:18,009 - langgraph_use2 - WARNING - 第 11 个测试点失败（第 3 次）: call_model2() got an unexpected keyword argument 'max_tokens'
Traceback (most recent call last):
  File "D:\pythonProject\generateTestCases\langgraph_use2.py", line 122, in generate_case
    resp = await call_model2(prompt, max_tokens=800)
                 ^^^^^^^^^^^^^^^^^^^^^^^^^^^^^^^^^^^
TypeError: call_model2() got an unexpected keyword argument 'max_tokens'

2025-07-05 23:25:18,009 - langgraph_use2 - INFO - 生成第 4 个用例，第 3 次尝试
2025-07-05 23:25:18,009 - langgraph_use2 - WARNING - 第 4 个测试点失败（第 3 次）: call_model2() got an unexpected keyword argument 'max_tokens'
Traceback (most recent call last):
  File "D:\pythonProject\generateTestCases\langgraph_use2.py", line 122, in generate_case
    resp = await call_model2(prompt, max_tokens=800)
                 ^^^^^^^^^^^^^^^^^^^^^^^^^^^^^^^^^^^
TypeError: call_model2() got an unexpected keyword argument 'max_tokens'

2025-07-05 23:25:18,009 - langgraph_use2 - INFO - 生成第 15 个用例，第 3 次尝试
2025-07-05 23:25:18,009 - langgraph_use2 - WARNING - 第 15 个测试点失败（第 3 次）: call_model2() got an unexpected keyword argument 'max_tokens'
Traceback (most recent call last):
  File "D:\pythonProject\generateTestCases\langgraph_use2.py", line 122, in generate_case
    resp = await call_model2(prompt, max_tokens=800)
                 ^^^^^^^^^^^^^^^^^^^^^^^^^^^^^^^^^^^
TypeError: call_model2() got an unexpected keyword argument 'max_tokens'

2025-07-05 23:25:18,009 - langgraph_use2 - INFO - 生成第 16 个用例，第 3 次尝试
2025-07-05 23:25:18,009 - langgraph_use2 - WARNING - 第 16 个测试点失败（第 3 次）: call_model2() got an unexpected keyword argument 'max_tokens'
Traceback (most recent call last):
  File "D:\pythonProject\generateTestCases\langgraph_use2.py", line 122, in generate_case
    resp = await call_model2(prompt, max_tokens=800)
                 ^^^^^^^^^^^^^^^^^^^^^^^^^^^^^^^^^^^
TypeError: call_model2() got an unexpected keyword argument 'max_tokens'

2025-07-05 23:25:18,009 - langgraph_use2 - INFO - 生成第 17 个用例，第 3 次尝试
2025-07-05 23:25:18,009 - langgraph_use2 - WARNING - 第 17 个测试点失败（第 3 次）: call_model2() got an unexpected keyword argument 'max_tokens'
Traceback (most recent call last):
  File "D:\pythonProject\generateTestCases\langgraph_use2.py", line 122, in generate_case
    resp = await call_model2(prompt, max_tokens=800)
                 ^^^^^^^^^^^^^^^^^^^^^^^^^^^^^^^^^^^
TypeError: call_model2() got an unexpected keyword argument 'max_tokens'

2025-07-05 23:25:18,011 - langgraph_use2 - INFO - 生成第 13 个用例，第 3 次尝试
2025-07-05 23:25:18,011 - langgraph_use2 - WARNING - 第 13 个测试点失败（第 3 次）: call_model2() got an unexpected keyword argument 'max_tokens'
Traceback (most recent call last):
  File "D:\pythonProject\generateTestCases\langgraph_use2.py", line 122, in generate_case
    resp = await call_model2(prompt, max_tokens=800)
                 ^^^^^^^^^^^^^^^^^^^^^^^^^^^^^^^^^^^
TypeError: call_model2() got an unexpected keyword argument 'max_tokens'

2025-07-05 23:25:18,011 - langgraph_use2 - INFO - 生成第 21 个用例，第 3 次尝试
2025-07-05 23:25:18,011 - langgraph_use2 - WARNING - 第 21 个测试点失败（第 3 次）: call_model2() got an unexpected keyword argument 'max_tokens'
Traceback (most recent call last):
  File "D:\pythonProject\generateTestCases\langgraph_use2.py", line 122, in generate_case
    resp = await call_model2(prompt, max_tokens=800)
                 ^^^^^^^^^^^^^^^^^^^^^^^^^^^^^^^^^^^
TypeError: call_model2() got an unexpected keyword argument 'max_tokens'

2025-07-05 23:25:18,011 - langgraph_use2 - INFO - 生成第 22 个用例，第 3 次尝试
2025-07-05 23:25:18,011 - langgraph_use2 - WARNING - 第 22 个测试点失败（第 3 次）: call_model2() got an unexpected keyword argument 'max_tokens'
Traceback (most recent call last):
  File "D:\pythonProject\generateTestCases\langgraph_use2.py", line 122, in generate_case
    resp = await call_model2(prompt, max_tokens=800)
                 ^^^^^^^^^^^^^^^^^^^^^^^^^^^^^^^^^^^
TypeError: call_model2() got an unexpected keyword argument 'max_tokens'

2025-07-05 23:25:18,011 - langgraph_use2 - INFO - 生成第 23 个用例，第 3 次尝试
2025-07-05 23:25:18,012 - langgraph_use2 - WARNING - 第 23 个测试点失败（第 3 次）: call_model2() got an unexpected keyword argument 'max_tokens'
Traceback (most recent call last):
  File "D:\pythonProject\generateTestCases\langgraph_use2.py", line 122, in generate_case
    resp = await call_model2(prompt, max_tokens=800)
                 ^^^^^^^^^^^^^^^^^^^^^^^^^^^^^^^^^^^
TypeError: call_model2() got an unexpected keyword argument 'max_tokens'

2025-07-05 23:25:18,012 - langgraph_use2 - INFO - 生成第 24 个用例，第 3 次尝试
2025-07-05 23:25:18,012 - langgraph_use2 - WARNING - 第 24 个测试点失败（第 3 次）: call_model2() got an unexpected keyword argument 'max_tokens'
Traceback (most recent call last):
  File "D:\pythonProject\generateTestCases\langgraph_use2.py", line 122, in generate_case
    resp = await call_model2(prompt, max_tokens=800)
                 ^^^^^^^^^^^^^^^^^^^^^^^^^^^^^^^^^^^
TypeError: call_model2() got an unexpected keyword argument 'max_tokens'

2025-07-05 23:25:18,012 - langgraph_use2 - INFO - 生成第 25 个用例，第 3 次尝试
2025-07-05 23:25:18,012 - langgraph_use2 - WARNING - 第 25 个测试点失败（第 3 次）: call_model2() got an unexpected keyword argument 'max_tokens'
Traceback (most recent call last):
  File "D:\pythonProject\generateTestCases\langgraph_use2.py", line 122, in generate_case
    resp = await call_model2(prompt, max_tokens=800)
                 ^^^^^^^^^^^^^^^^^^^^^^^^^^^^^^^^^^^
TypeError: call_model2() got an unexpected keyword argument 'max_tokens'

2025-07-05 23:25:18,012 - langgraph_use2 - INFO - 生成第 18 个用例，第 3 次尝试
2025-07-05 23:25:18,012 - langgraph_use2 - WARNING - 第 18 个测试点失败（第 3 次）: call_model2() got an unexpected keyword argument 'max_tokens'
Traceback (most recent call last):
  File "D:\pythonProject\generateTestCases\langgraph_use2.py", line 122, in generate_case
    resp = await call_model2(prompt, max_tokens=800)
                 ^^^^^^^^^^^^^^^^^^^^^^^^^^^^^^^^^^^
TypeError: call_model2() got an unexpected keyword argument 'max_tokens'

2025-07-05 23:25:18,012 - langgraph_use2 - INFO - 生成第 5 个用例，第 3 次尝试
2025-07-05 23:25:18,012 - langgraph_use2 - WARNING - 第 5 个测试点失败（第 3 次）: call_model2() got an unexpected keyword argument 'max_tokens'
Traceback (most recent call last):
  File "D:\pythonProject\generateTestCases\langgraph_use2.py", line 122, in generate_case
    resp = await call_model2(prompt, max_tokens=800)
                 ^^^^^^^^^^^^^^^^^^^^^^^^^^^^^^^^^^^
TypeError: call_model2() got an unexpected keyword argument 'max_tokens'

2025-07-05 23:25:18,012 - langgraph_use2 - INFO - 生成第 12 个用例，第 3 次尝试
2025-07-05 23:25:18,013 - langgraph_use2 - WARNING - 第 12 个测试点失败（第 3 次）: call_model2() got an unexpected keyword argument 'max_tokens'
Traceback (most recent call last):
  File "D:\pythonProject\generateTestCases\langgraph_use2.py", line 122, in generate_case
    resp = await call_model2(prompt, max_tokens=800)
                 ^^^^^^^^^^^^^^^^^^^^^^^^^^^^^^^^^^^
TypeError: call_model2() got an unexpected keyword argument 'max_tokens'

2025-07-05 23:25:18,013 - langgraph_use2 - INFO - 生成第 26 个用例，第 3 次尝试
2025-07-05 23:25:18,013 - langgraph_use2 - WARNING - 第 26 个测试点失败（第 3 次）: call_model2() got an unexpected keyword argument 'max_tokens'
Traceback (most recent call last):
  File "D:\pythonProject\generateTestCases\langgraph_use2.py", line 122, in generate_case
    resp = await call_model2(prompt, max_tokens=800)
                 ^^^^^^^^^^^^^^^^^^^^^^^^^^^^^^^^^^^
TypeError: call_model2() got an unexpected keyword argument 'max_tokens'

2025-07-05 23:25:19,028 - langgraph_use2 - ERROR - 第 1 个用例多次失败，跳过: NoneType: None

2025-07-05 23:25:19,029 - langgraph_use2 - ERROR - 第 20 个用例多次失败，跳过: NoneType: None

2025-07-05 23:25:19,029 - langgraph_use2 - ERROR - 第 2 个用例多次失败，跳过: NoneType: None

2025-07-05 23:25:19,029 - langgraph_use2 - ERROR - 第 15 个用例多次失败，跳过: NoneType: None

2025-07-05 23:25:19,030 - langgraph_use2 - ERROR - 第 4 个用例多次失败，跳过: NoneType: None

2025-07-05 23:25:19,030 - langgraph_use2 - ERROR - 第 26 个用例多次失败，跳过: NoneType: None

2025-07-05 23:25:19,030 - langgraph_use2 - ERROR - 第 12 个用例多次失败，跳过: NoneType: None

2025-07-05 23:25:19,030 - langgraph_use2 - ERROR - 第 5 个用例多次失败，跳过: NoneType: None

2025-07-05 23:25:19,030 - langgraph_use2 - ERROR - 第 18 个用例多次失败，跳过: NoneType: None

2025-07-05 23:25:19,031 - langgraph_use2 - ERROR - 第 25 个用例多次失败，跳过: NoneType: None

2025-07-05 23:25:19,031 - langgraph_use2 - ERROR - 第 24 个用例多次失败，跳过: NoneType: None

2025-07-05 23:25:19,031 - langgraph_use2 - ERROR - 第 23 个用例多次失败，跳过: NoneType: None

2025-07-05 23:25:19,031 - langgraph_use2 - ERROR - 第 22 个用例多次失败，跳过: NoneType: None

2025-07-05 23:25:19,031 - langgraph_use2 - ERROR - 第 21 个用例多次失败，跳过: NoneType: None

2025-07-05 23:25:19,031 - langgraph_use2 - ERROR - 第 13 个用例多次失败，跳过: NoneType: None

2025-07-05 23:25:19,032 - langgraph_use2 - ERROR - 第 17 个用例多次失败，跳过: NoneType: None

2025-07-05 23:25:19,032 - langgraph_use2 - ERROR - 第 16 个用例多次失败，跳过: NoneType: None

2025-07-05 23:25:19,032 - langgraph_use2 - ERROR - 第 3 个用例多次失败，跳过: NoneType: None

2025-07-05 23:25:19,032 - langgraph_use2 - ERROR - 第 10 个用例多次失败，跳过: NoneType: None

2025-07-05 23:25:19,032 - langgraph_use2 - ERROR - 第 11 个用例多次失败，跳过: NoneType: None

2025-07-05 23:25:19,033 - langgraph_use2 - ERROR - 第 9 个用例多次失败，跳过: NoneType: None

2025-07-05 23:25:19,033 - langgraph_use2 - ERROR - 第 8 个用例多次失败，跳过: NoneType: None

2025-07-05 23:25:19,033 - langgraph_use2 - ERROR - 第 7 个用例多次失败，跳过: NoneType: None

2025-07-05 23:25:19,033 - langgraph_use2 - ERROR - 第 14 个用例多次失败，跳过: NoneType: None

2025-07-05 23:25:19,033 - langgraph_use2 - ERROR - 第 27 个用例多次失败，跳过: NoneType: None

2025-07-05 23:25:19,033 - langgraph_use2 - ERROR - 第 19 个用例多次失败，跳过: NoneType: None

2025-07-05 23:25:19,033 - langgraph_use2 - ERROR - 第 6 个用例多次失败，跳过: NoneType: None

2025-07-05 23:25:19,034 - langgraph_use2 - INFO - [Step 4] 用例生成完成: 成功 0 个，失败 27 个，用时 3.06s
2025-07-05 23:25:19,035 - langgraph_use2 - INFO - [Step 5] 校验测试用例，移除高度一致的重复项
2025-07-05 23:25:19,036 - langgraph_use2 - WARNING - 无测试用例可校验
2025-07-05 23:25:19,036 - main - INFO - 生成测试用例成功，耗时 135.94 秒
2025-07-05 23:26:49,361 - uvicorn.error - INFO - Shutting down
2025-07-05 23:26:49,471 - uvicorn.error - INFO - Waiting for application shutdown.
2025-07-05 23:26:49,471 - uvicorn.error - INFO - Application shutdown complete.
2025-07-05 23:26:49,471 - uvicorn.error - INFO - Finished server process [10248]
